Workbook

Sheet Summary
A1: Ver 2 | C1: Location | D1: Date
A2: Supplies for: | C2: PC | D2: 46131 | F2: Location
A3: Date quoted: | D3: 46126 | F3: BL | G3: Boon Lay
F4: LK | G4: Leng Kee
A5: S/No | B5: Worksheet | C5: Sub Total | F5: PC | G5: Punggol
A6: 1 | B6: Frozen Food | C6: ='Frozen Food'!J44 -> 16665.5 | F6: SNM | G6: Nee Soon Central CC
A7: 2 | B7: Beverages | C7: =Beverages!J28 -> 5217.2 | F7: TN | G7: Tampines North
A8: 3 | B8: Groceries & Breakfast | C8: ='Groceries & Breakfast'!J30 -> 8402.16
A9: 4 | B9: Rice & Oil | C9: ='Rice & Oil'!J33 -> 18289.54
A10: 5 | B10: Canned Food & Condiment | C10: ='Canned Food & Condiment'!J36 -> 4922.91
A11: 6 | B11: Snacks | C11: ='Snacks '!J32 -> 5211.56
A12: 7 | B12: Tissue & Others | C12: ='Tissue & Others'!J38 -> 17577.6
A13: 8 | B13: Cleaning Agent | C13: ='Cleaning Agent'!J42 -> 9200.54
A14: Total | C14: =SUM(C6:C13) -> 85487.01

Sheet Frozen Food
A1: Ver 2 | B1: Frozen Food | I1: =Summary!D2 -> 46131
A3: Item No. | B3: Type | C3: Barcode | D3: Item Code | E3: Brand and Product Description | F3: Pack Size | G3: Price | H3: Unit Price | I3: Beginning Units | J3: Total Cost
A4: 1 | B4: NA | C4: 7898312045351 | D4: 205457 | E4: AVIVAR CKN MIDJOINT WING 2KG | F4: 6 | G4: 9.95 | H4: 9.95 | I4: 150 | J4: =I4*H4 -> 1492.5
A5: 2 | C5: 7894904055364 | D5: 200268 | E5: SEARA FRZ CKN WINGS 2KG | F5: 6 | G5: 7.95 | H5: 7.95 | I5: 198 | J5: =I5*H5 -> 1574.1
A6: 3 | C6: 8888626607429 | D6: 205542 | E6: T/BITES ROASTED CKN HOT WINGSTICK 1KG | F6: 10 | G6: 12.95 | H6: 12.95 | I6: 70 | J6: =I6*H6 -> 906.5
A7: 4 | C7: 8888626607795 | D7: 206083 | E7: T/BITES ROASTED CKN BUFFALO W/STICK 1KG | F7: 10 | G7: 12.45 | H7: 12.45 | I7: 60 | J7: =I7*H7 -> 747
A8: 5 | C8: 8888626606859 | D8: 205115 | E8: TASTY BITES PRAWN PASTE CKN WING 700G | F8: 20 | G8: 14.95 | H8: 14.95 | I8: 60 | J8: =I8*H8 -> 897
A9: 6 | C9: 8888626143347 | D9: 205362 | E9: T/BITES CURRY SAMOSA 500G | F9: 20 | G9: 4.25 | H9: 4.25 | I9: 40 | J9: =I9*H9 -> 170
A10: 7 | C10: 8888626608617 | D10: 206492 | E10: T/BITES ROASTED CHICKEN THIGH 450G | F10: 20 | G10: 4.95 | H10: 4.95 | I10: 40 | J10: =I10*H10 -> 198
A11: 8 | C11: 8888626002040 | D11: 202307 | E11: T/BITES CRISPY CKN W BC WRAP 450G | F11: 12 | G11: 6.95 | H11: 6.95 | I11: 24 | J11: =I11*H11 -> 166.8
A12: 9 | C12: 8888626607559 | D12: 205766 | E12: T/BITES ROASTED CKN YAKITORI(TERIYAKI) | F12: 30 | G12: 3.3 | H12: 3.3 | I12: 90 | J12: =I12*H12 -> 297
A13: 10 | C13: 8888626606613 | D13: 204784 | E13: GOLDEN SWISS KANIMI CHUNK 180G | F13: 20 | G13: 3.75 | H13: 3.75 | I13: 60 | J13: =I13*H13 -> 225
A14: 11 | C14: 8888626606965 | D14: 205144 | E14: TASTY BITES CHEEZY CHICKEN MEATBALL 350G | F14: 12 | G14: 6.25 | H14: 6.25 | I14: 36 | J14: =I14*H14 -> 225
A15: 12 | C15: 8888626606828 | D15: 204962 | E15: TASTY BITES CHEEZY CUTTLEFISH BALL 200G | F15: 20 | G15: 4.95 | H15: 4.95 | I15: 20 | J15: =I15*H15 -> 99
A16: 13 | C16: 8888626606439 | D16: 204556 | E16: TASTY BITES G. CHEESE FINGER (20S) 500G | F16: 20 | G16: 4.95 | H16: 4.95 | I16: 40 | J16: =I16*H16 -> 198
... A35: 32 | C35: 8888626608556 | D35: 206494 | E35: T/BITES JAPANESE STYLE PRAWN GYOZA 200G | F35: 20 | G35: 2.5 | H35: 2.5 | I35: 60 | J35: =I35*H35 -> 150
A36: 33 | C36: 8888626029528/ 8888626608778 | D36: 202612 | E36: T/BITES CRINKLE CUT FRENCH FRIES 1KG (NEW ARRIVAL) | F36: 10 | G36: 3.25 | H36: 3.25 | I36: 50 | J36: =I36*H36 -> 162.5
A37: 34 | C37: 8888626029535/ 8888626608761 | D37: 202613 | E37: T/BITES SHOESTRING FRENCH FRIES 1KG (NEW ARRIVAL) | F37: 10 | G37: 3.25 | H37: 3.25 | I37: 20 | J37: =I37*H37 -> 65
A38: 35 | C38: 8888626607634 | D38: 206609 | E38: T/BITES CKN BREAST(SWEET&SPICY)5S 325G (NEW ARRIVAL) | F38: 20 | G38: 4.5 | H38: 4.5 | I38: 40 | J38: =I38*H38 -> 180
A39: 36 | C39: 8888626606538 | D39: 204741 | E39: TASTY BITES CHICKEN KARAAGE 450G | F39: 20 | G39: 5.75 | H39: 5.75 | I39: 40 | J39: =I39*H39 -> 230
A40: 37 | C40: 8888626608969 | D40: 206581 | E40: T/BITES R/HONEY CKN MID WINGS 380G (NEW ARRIVAL) | F40: 20 | G40: 7.95 | H40: 7.95 | I40: 40 | J40: =I40*H40 -> 318
A41: 38 | B41: Pizza | C41: 8888626005379 | D41: 202327 | E41: T/BITES PIZZA CLASSIC CHEESE 2S | F41: 12 | G41: 7.95 | H41: 7.95 | I41: 72 | J41: =I41*H41 -> 572.4
A42: 39 | C42: 8888626005362 | D42: 202326 | E42: T/BITES PIZZA HAWAIIAN 2S | F42: 12 | G42: 7.95 | H42: 7.95 | I42: 60 | J42: =I42*H42 -> 477
A43: 40 | B43: Prata | C43: 8888626002071 | D43: 202312 | E43: T/BITES ROTI PRATA PLAIN 325G | F43: 24 | G43: 1.95 | H43: 1.95 | I43: 120 | J43: =I43*H43 -> 234
A44: Total | J44: =SUM(J4:J43) -> 16665.5

Sheet Beverages
A1: Ver 2 | B1: Beverages | I1: =Summary!D2 -> 46131
A3: Item No. | B3: Type | C3: Barcode | D3: Item Code | E3: Brand and Product Description | F3: Pack Size | G3: Price | H3: Unit Price | I3: Beginning Units | J3: Total Cost
A4: 1 | B4: Beverage -Elder | C4: 9415007058090 | D4: 772533 | E4: ANLENE GOLD 5X PLAIN 550G | F4: 12 | G4: 14.95 | H4: 14.95 | I4: 48 | J4: =I4*H4 -> 717.6
A5: 2 | B5: NA | C5: 8888626174372 | D5: 433088 | E5: HAPPY FAMILY SOY MILK DRINK OAT 300ML | F5: 24 | G5: 0.75 | H5: 0.75 | I5: 48 | J5: =I5*H5 -> 36
A6: 3 | C6: 8888626174365 | D6: 433086 | E6: HAPPY FAMILY SOY MILK DRINK 300ML | F6: 24 | G6: 0.75 | H6: 0.75 | I6: 48 | J6: =I6*H6 -> 36
A7: 4 | C7: 8888626167947 | D7: 432763 | E7: HERITAGE FARM UHT FULL CREAM MILK 1L | F7: 6 | G7: 1.9 | H7: 1.9 | I7: 318 | J7: =I7*H7 -> 604.2
A8: 5 | C8: 8888626167954 | D8: 432764 | E8: HERITAGE FARM UHT LOW FAT MILK 1L | F8: 6 | G8: 1.9 | H8: 1.9 | I8: 84 | J8: =I8*H8 -> 159.6
A9: 6 | C9: 8888026443023 / 9557305000552 | D9: 770022 | E9: MARIGOLD UHT CHOCO MILK 1L | F9: 12 | G9: 2 | H9: 2 | I9: 180 | J9: =I9*H9 -> 360
A10: 7 | C10: 8888626144375 | D10: 431206 | E10: HERITAGE FARM MILK TEA 15X36G | F10: 24 | G10: 6.5 | H10: 6.5 | I10: 48 | J10: =I10*H10 -> 312
A11: 8 | C11: 8888626174419 | D11: 433098 | E11: H/FARM STARFRUIT JUICE 480ML | F11: 24 | G11: 0.95 | H11: 0.95 | I11: 24 | J11: =I11*H11 -> 22.8
A12: 9 | C12: 8888626174419 | D12: 433100 | E12: H/FARM RED S'CANE&W'CHESTNUT 480ML | F12: 24 | G12: 0.95 | H12: 0.95 | I12: 72 | J12: =I12*H12 -> 68.4
A13: 10 | C13: 8888626174402 | D13: 433102 | E13: H/FARM PLUM&PASSION FRUIT 480ML | F13: 24 | G13: 0.95 | H13: 0.95 | I13: 48 | J13: =I13*H13 -> 45.6
A14: 11 | C14: 8888626174389 | D14: 433104 | E14: H/FARM GOLDEN PEAR&ALOE VERA 480ML | F14: 24 | G14: 0.95 | H14: 0.95 | I14: 72 | J14: =I14*H14 -> 68.4
A15: 12 | C15: 8888626167756 | D15: 432419 | E15: HERITAGE FARM CHOCO MALT DRINK 15SX30G | F15: 24 | G15: 5.95 | H15: 5.95 | I15: 24 | J15: =I15*H15 -> 142.8
A16: 13 | C16: 8888626150536 | D16: 431526 | E16: HERITAGE FARM PREMIUM S/COFFEE 200G+50G | F16: 6 | G16: 10.95 | H16: 10.95 | I16: 48 | J16: =I16*H16 -> 525.6
A17: 14 | C17: 9557305000576 | D17: 425092 | E17: MARIGOLD ASIAN DRINK SOYABEAN L/SWEET 1L | F17: 12 | G17: 1.2 | H17: 1.2 | I17: 108 | J17: =I17*H17 -> 129.6
A18: 15 | C18: 8888026445003 | D18: 428747 | E18: M'GOLD UHT CHOCOLATE MILK 6X200ML | F18: 4 | G18: 3.75 | H18: 3.75 | I18: 100 | J18: =I18*H18 -> 375
A19: 16 | C19: 8888626167756 | D19: 432419 | E19: HERITAGE FARM CHOCO MALT DRINK 15SX30G | F19: 24 | G19: 5.95 | H19: 5.95 | I19: 24 | J19: =I19*H19 -> 142.8
A20: 17 | C20: 8888626155104 | D20: 485509 | E20: H/FAMILY NATURAL HONEY 1KG | F20: 12 | G20: 5.2 | H20: 5.2 | I20: 24 | J20: =I20*H20 -> 124.8
A21: 18 | C21: 8888626141138 | D21: 430793 | E21: HERITAGE FARM 3IN1 CEREAL&OAT DRK 18X30G | F21: 20 | G21: 3.65 | H21: 3.65 | I21: 40 | J21: =I21*H21 -> 146
... A24: 21 | C24: 8888626160436 | D24: 432032 | E24: HERITAGE FARM ORG COCONUT WATER 1L | F24: 12 | G24: 2.5 | H24: 2.5 | I24: 180 | J24: =I24*H24 -> 450
A25: 22 | B25: Condensed Milk | C25: 8888626174976 | D25: 772590 | E25: H/FAMILY SWEETENED CREAMER 1KG | F25: 12 | G25: 2.5 | H25: 2.5 | I25: 24 | J25: =I25*H25 -> 60
A26: 23 | C26: 8888026303037 / 8888026303105 | D26: 770219 | E26: DAWN SWEETENER 380G | F26: 48 | G26: 1.35 | H26: 1.35 | I26: 192 | J26: =I26*H26 -> 259.2
A27: 24 | B27: Green Tea | C27: 8888626159874 | D27: 431917 | E27: HERITAGE FARM GREEN TEA 50X1.5G | F27: 12 | G27: 4.45 | H27: 4.45 | I27: 24 | J27: =I27*H27 -> 106.8
A28: Total | J28: =SUM(J4:J27) -> 5217.2

Sheet Groceries & Breakfast
A1: Ver 2 | B1: Groceries & Breakfast | I1: =Summary!D2 -> 46131
A3: Item No. | B3: Type | C3: Barcode | D3: Item Code | E3: Brand and Product Description | F3: Pack Size | G3: Price | H3: Unit Price | I3: Beginning Units | J3: Total Cost
A4: 1 | B4: Eggs | C4: 8888626140926 | D4: 520272 | E4: HERITAGE SINGAPORE FARM EGGS 10+2S(660G) | F4: 25 | G4: 4.05 | H4: 4.05 | I4: 200 | J4: =I4*H4 -> 810
A5: 2 | C5: 8888626088563 / 8885008965559 | D5: 520183 | E5: EGG FOR YOU FRESH EGG'S 30S (1650G) PEP | F5: 120 | G5: 6.65 | H5: 6.65 | I5: 600 | J5: =I5*H5 -> 3990
A6: 3 | B6: Spread | C6: 8888626117683 | D6: 485012 | E6: BAKE FOR YOU NONYA KAYA 400G | F6: 24 | G6: 3.65 | H6: 3.65 | I6: 48 | J6: =I6*H6 -> 175.2
A7: 4 | C7: 8888626174662 | D7: 485938 | E7: BAKE FOR YOU XO KAYA(LESS SUGAR)410G | F7: 12 | G7: 4.99 | H7: 4.99 | I7: 24 | J7: =I7*H7 -> 119.76
A8: 5 | C8: 8888626127927 | D8: 485067 | E8: BAKE FOR YOU PEANUT BUTTER CREAMY 510G | F8: 12 | G8: 3.55 | H8: 3.55 | I8: 24 | J8: =I8*H8 -> 85.2
A9: 6 | C9: 8888626127934 | D9: 485068 | E9: BAKE FOR YOU PEANUT BUTTER CRUNCHY 510G | F9: 12 | G9: 3.55 | H9: 3.55 | I9: 24 | J9: =I9*H9 -> 85.2
A10: 7 | C10: 8888626150512 | D10: 485476 | E10: HERITAGE FARM CHOCO H'LNUT SPREAD 350G | F10: 12 | G10: 4.5 | H10: 4.5 | I10: 36 | J10: =I10*H10 -> 162
A11: 8 | B11: Bread | C11: 8888626103341 | D11: 484893 | E11: BAKE FOR YOU ENRICHED W/M W/BREAD 400G | F11: 1 | G11: 2.3 | H11: 2.3 | I11: 20 | J11: =I11*H11 -> 46
A12: 9 | C12: 8888626103327 | D12: 484891 | E12: BAKE FOR YOU JUMBO ENRICHED W/BREAD 600G | F12: 1 | G12: 2.5 | H12: 2.5 | I12: 45 | J12: =I12*H12 -> 112.5
A13: 10 | C13: 8888626103310 | D13: 484890 | E13: BAKE FOR YOU J/ENRICHED W/M W/BREAD 600G | F13: 1 | G13: 2.95 | H13: 2.95 | I13: 50 | J13: =I13*H13 -> 147.5
A14: 11 | B14: Vermicelli | C14: 8888626095691 | D14: 662200 | E14: H/FAMILY RED CARGO RICE VERMICELLI 400G | F14: 10 | G14: 1.75 | H14: 1.75 | I14: 30 | J14: =I14*H14 -> 52.5
A15: 12 | C15: 8888626158747 | D15: 663324 | E15: HERITAGE FARM THAI VERMICELLI 500G | F15: 10 | G15: 2.6 | H15: 2.6 | I15: 30 | J15: =I15*H15 -> 78
A16: 13 | C16: 8888626157283 | D16: 663325 | E16: HERITAGE FARM THAI VERMICELLI 375G | F16: 10 | G16: 1.3 | H16: 1.3 | I16: 60 | J16: =I16*H16 -> 78
A17: 14 | C17: 8888626102290 | D17: 662248 | E17: H/FAMILY FLOUR VERMICELLI 250G | F17: 16 | G17: 1.25 | H17: 1.25 | I17: 48 | J17: =I17*H17 -> 60
A18: 15 | B18: Dried Food | C18: 8888626204260 | D18: 344180 | E18: H/F DRIED MUSHROOM 4-5 BAI HUA 200G | F18: 5 | G18: 10.85 | H18: 10.85 | I18: 50 | J18: =I18*H18 -> 542.5
A19: 16 | C19: 8888626014784 | D19: 105663 | E19: H/FAMILY PLAIN FLOUR 1KG | F19: 12 | G19: 1.98 | H19: 1.98 | I19: 60 | J19: =I19*H19 -> 118.8
A20: 17 | C20: 8886303210207 | D20: 101086 | E20: KARA COCONUT CREAM 200ML | F20: 30 | G20: 1.2 | H20: 1.2 | I20: 390 | J20: =I20*H20 -> 468
A21: 18 | C21: 8888626094021 | D21: 344407 | E21: DRIED SHRIMP(F5)100G | F21: 10 | G21: 3.8 | H21: 3.8 | I21: 80 | J21: =I21*H21 -> 304
A22: 19 | B22: NA | C22: 8888626141176 | D22: 662763 | E22: HAPPY FAMILY FRESH JAPANESE UDON 200G | F22: 30 | G22: 0.9 | H22: 0.9 | I22: 90 | J22: =I22*H22 -> 81
A23: 20 | C23: 8888626143637 | D23: 662813 | E23: HERITAGE FARM SLICED NOODLES 600G | F23: 12 | G23: 4.2 | H23: 4.2 | I23: 48 | J23: =I23*H23 -> 201.6
A24: 21 | C24: 8888626143613 | D24: 662814 | E24: HERITAGE FARM RAMEN NOODLES 600G | F24: 12 | G24: 4.2 | H24: 4.2 | I24: 48 | J24: =I24*H24 -> 201.6
A25: 22 | C25: 8888626167435 | D25: 663113 | E25: H/FAMILY CURRY INSTANT NOODLE 5X78G(N) | F25: 6 | G25: 1.7 | H25: 1.7 | I25: 24 | J25: =I25*H25 -> 40.8
A26: 23 | C26: 8888626167428 | D26: 663115 | E26: H/FAMILY CHICKEN INSTANT NOODLE 5X80G(N) | F26: 6 | G26: 1.7 | H26: 1.7 | I26: 48 | J26: =I26*H26 -> 81.6
A27: 24 | C27: 8888626167442 | D27: 663114 | E27: H/FAMILY VEG INSTANT NOODLE 5X78G(N) | F27: 6 | G27: 1.7 | H27: 1.7 | I27: 12 | J27: =I27*H27 -> 20.4
A28: 25 | C28: 8888626069425 | D28: 661987 | E28: H/FAMILY EASI-COOK INSTANT NOODLES 700G | F28: 10 | G28: 2.3 | H28: 2.3 | I28: 80 | J28: =I28*H28 -> 184
A29: 26 | C29: 8888626117768 | D29: 662386 | E29: H/FAMILY YEE MEE 375G | F29: 20 | G29: 1.95 | H29: 1.95 | I29: 80 | J29: =I29*H29 -> 156
A30: Total | J30: =SUM(J4:J29) -> 8402.16

Sheet Rice & Oil
A1: Ver 2 | B1: Rice & Oil | I1: =Summary!D2 -> 46131
A3: Item No. | B3: Type | C3: Barcode | D3: Item Code | E3: Brand and Product Description | F3: Pack Size | G3: Price | H3: Unit Price | I3: Beginning Units | J3: Total Cost
A4: 1 | B4: Rice | C4: 8888626131030 | D4: 108371 | E4: HERITAGE FARM BASMATI RICE 5KG | F4: 4 | G4: 15.9 | H4: 15.9 | I4: 120 | J4: =I4*H4 -> 1908
A5: 2 | C5: 8888626129068 | D5: 108342 | E5: ROYAL G/GRAIN TAIWAN PEARL RICE 5KG | F5: 4 | G5: 13.5 | H5: 13.5 | I5: 80 | J5: =I5*H5 -> 1080
A6: 3 | C6: 8888626160443 | D6: 109164 | E6: NANG RUM THAI (VAC)5KG | F6: 4 | G6: 7.99 | H6: 7.99 | I6: 16 | J6: =I6*H6 -> 127.84
A7: 4 | C7: 8888626102733 | D7: 107876 | E7: HAPPY FAMILY PONNI RICE 5KG | F7: 5 | G7: 6.99 | H7: 6.99 | I7: 15 | J7: =I7*H7 -> 104.85
A8: 5 | C8: 8888626011240 | D8: 105508 | E8: H/FAMILY GLUTINOUS RICE 1KG | F8: 20 | G8: 1.99 | H8: 1.99 | I8: 20 | J8: =I8*H8 -> 39.8
A9: 6 | C9: 8888626155234 | D9: 109017 | E9: H/FAMILY FRAGRANT JASMINE RICE5KG(VAC) | F9: 3 | G9: 7.65 | H9: 7.65 | I9: 159 | J9: =I9*H9 -> 1216.35
A10: 7 | C10: 8888626138664 | D10: 108505 | E10: ROYAL G/GRAIN PREMIUM FRAG RICE 5KG | F10: 4 | G10: 13.5 | H10: 13.5 | I10: 80 | J10: =I10*H10 -> 1080
A11: 8 | C11: 8888626102726 | D11: 107877 | E11: ROYAL G/MALI PREMIUM FRAGRANT RICE 5KG | F11: 6 | G11: 12.99 | H11: 12.99 | I11: 222 | J11: =I11*H11 -> 2883.78
A12: 9 | C12: 8888626101927 | D12: 107802 | E12: ROYAL G/GRAIN MIXED RED C/RICE 2.5KG | F12: 10 | G12: 8.9 | H12: 8.9 | I12: 20 | J12: =I12*H12 -> 178
A13: 10 | C13: 8888626129075 | D13: 108352 | E13: HAPPY FAMILY 3 MIXED CARGO RICE 1.8KG | F13: 10 | G13: 6.5 | H13: 6.5 | I13: 10 | J13: =I13*H13 -> 65
A14: 11 | C14: 8888626129105 | D14: 108355 | E14: HAPPY FAMILY BROWN RICE 1.8KG | F14: 10 | G14: 4.25 | H14: 4.25 | I14: 20 | J14: =I14*H14 -> 85
A15: 12 | C15: 8888626095479 | D15: 107752 | E15: ROYAL G/GRAIN MIXED JASMINE RICE 2.5KG | F15: 10 | G15: 8.75 | H15: 8.75 | I15: 20 | J15: =I15*H15 -> 175
A16: 13 | C16: 8888626154985 | D16: 108979 | E16: ROYAL G/GRAIN THAI JASMINE BRW RICE2.5KG | F16: 6 | G16: 7.8 | H16: 7.8 | I16: 36 | J16: =I16*H16 -> 280.8
A17: 14 | B17: Oil | C17: 8888626140292 | D17: 108614 | E17: HERITAGE FARM GRAPESEED OIL 500ML | F17: 12 | G17: 6.5 | H17: 6.5 | I17: 12 | J17: =I17*H17 -> 78
A18: 15 | C18: 8888626115108 | D18: 108086 | E18: HERITAGE FARM EX VIRGIN OLIVE OIL 500ML | F18: 12 | G18: 7.9 | H18: 7.9 | I18: 60 | J18: =I18*H18 -> 474
A19: 16 | C19: 8888626167923 | D19: 109366 | E19: HERITAGE FARM CLASSIC OLIVE OIL 500ML | F19: 12 | G19: 5.9 | H19: 5.9 | I19: 24 | J19: =I19*H19 -> 141.6
A20: 17 | C20: 888626167930 | D20: 109367 | E20: HERITAGE FARM CLASSIC OLIVE OIL 1L | F20: 6 | G20: 13.9 | H20: 13.9 | I20: 30 | J20: =I20*H20 -> 417
A21: 18 | C21: 8888626118932 | D21: 108212 | E21: HERITAGE FARM EXTRA LIGHT OLIVE OIL 1L | F21: 6 | G21: 13.9 | H21: 13.9 | I21: 24 | J21: =I21*H21 -> 333.6
A22: 19 | C22: 8888626115139 | D22: 108085 | E22: HERITAGE FARM CLASSIC OLIVE OIL 2L | F22: 6 | G22: 19.99 | H22: 19.99 | I22: 48 | J22: =I22*H22 -> 959.52
A23: 20 | C23: 8888626118949 | D23: 108213 | E23: HERITAGE FARM EXTRA LIGHT OLIVE OIL 2L | F23: 6 | G23: 19.99 | H23: 19.99 | I23: 30 | J23: =I23*H23 -> 599.7
A24: 21 | C24: 8888626174518 | D24: 109620 | E24: HERITAGE FARM SUNFLOWER&OLIVE OIL 2L | F24: 6 | G24: 10.8 | H24: 10.8 | I24: 48 | J24: =I24*H24 -> 518.4
A25: 22 | C25: 8888626157122 | D25: 109053 | E25: HERITAGE FARM PRE CANOLA S.FLOWER OIL 2L | F25: 6 | G25: 8.5 | H25: 8.5 | I25: 30 | J25: =I25*H25 -> 255
A26: 23 | C26: 8888626104980 | D26: 107917 | E26: H/FAMILY CANOLA OIL 3L | F26: 4 | G26: 8.9 | H26: 8.9 | I26: 96 | J26: =I26*H26 -> 854.4
A27: 24 | C27: 8888626095042 | D27: 107737 | E27: HAPPY FAMILY RICE BRAN OIL 2L | F27: 6 | G27: 8.5 | H27: 8.5 | I27: 24 | J27: =I27*H27 -> 204
A28: 25 | C28: 8888626095059 | D28: 107738 | E28: HAPPY FAMILY RICE BRAN OIL 5L | F28: 4 | G28: 19.95 | H28: 19.95 | I28: 32 | J28: =I28*H28 -> 638.4
A29: 26 | C29: 8888626044224 | D29: 106166 | E29: H/FAMILY VEGETABLE OIL 2L | F29: 6 | G29: 4.95 | H29: 4.95 | I29: 42 | J29: =I29*H29 -> 207.9
A30: 27 | C30: 8888626017372 | D30: 105732 | E30: H/FAMILY VEGETABLE OIL 5L | F30: 4 | G30: 10.95 | H30: 10.95 | I30: 144 | J30: =I30*H30 -> 1576.8
A31: 28 | C31: 8888626105000 | D31: 107919 | E31: H/FAMILY GROUNDNUT OIL 2L | F31: 6 | G31: 10.95 | H31: 10.95 | I31: 24 | J31: =I31*H31 -> 262.8
A32: 29 | C32: 8888626080628 | D32: 107371 | E32: H/FAMILY SUNFLOWER OIL 3L | F32: 4 | G32: 9.65 | H32: 9.65 | I32: 160 | J32: =I32*H32 -> 1544
A33: Total | J33: =SUM(J4:J32) -> 18289.54

Sheet Canned Food & Condiment
A1: Ver 2 | B1: Canned Food | I1: =Summary!D2 -> 46131
A3: Item No. | B3: Type | C3: Barcode | D3: Item Code | E3: Brand and Product Description | F3: Pack Size | G3: Price | H3: Unit Price | I3: Beginning Units | J3: Total Cost
A4: 1 | B4: Tuna | C4: 8888626173474 | D4: 702792 | E4: H/FAMILY YFIN TUNA CHUNK IN SFOIL 170G | F4: 24 | G4: 2.5 | H4: 2.5 | I4: 72 | J4: =I4*H4 -> 180
A5: 2 | C5: 8888626173481 | D5: 702793 | E5: H/FAMILY YFIN TUNA CHUNK IN BRINE 170G | F5: 24 | G5: 2.5 | H5: 2.5 | I5: 72 | J5: =I5*H5 -> 180
A6: 3 | C6: 8888626056012 | D6: 701742 | E6: H/FAMILY TUNA MAYONNAISE 170G | F6: 24 | G6: 2.5 | H6: 2.5 | I6: 48 | J6: =I6*H6 -> 120
A7: 4 | B7: Chicken Curry | C7: 8888626174426 | D7: 702842 | E7: H/FAMILY CHICKEN CURRY W/POTATOES 300G | F7: 24 | G7: 2.9 | H7: 2.9 | I7: 48 | J7: =I7*H7 -> 139.2
A8: 5 | B8: NA | C8: 8888626155326 | D8: 702679 | E8: H/FAMILY BRAISED PEANUTS 170G | F8: 48 | G8: 0.65 | H8: 0.65 | I8: 96 | J8: =I8*H8 -> 62.4
A9: 6 | C9: 8888626155333 | D9: 702680 | E9: H/FAMILY PICKLED LETTUCE 170G | F9: 24 | G9: 0.85 | H9: 0.85 | I9: 72 | J9: =I9*H9 -> 61.2
A10: 7 | C10: 8888626025025 | D10: 701544 | E10: H/FAMILY SARDINE IN TOMATO SAUCE 425G | F10: 24 | G10: 2.8 | H10: 2.8 | I10: 120 | J10: =I10*H10 -> 336
A11: 8 | C11: 8888626062129 | D11: 701799 | E11: H/FAMILY MACKEREL IN TOMATO SAUCE 425G | F11: 24 | G11: 1.5 | H11: 1.5 | I11: 48 | J11: =I11*H11 -> 72
A12: 9 | C12: 051000043764/ 0051000043764 | D12: 700196 | E12: CAMPBELL'S CREAM OF MUSHROOM 290G | F12: 24 | G12: 2.1 | H12: 2.1 | I12: 120 | J12: =I12*H12 -> 252
A13: 10 | C13: 8888626025032 | D13: 701545 | E13: H/FAMILY BAKED BEAN TMT SAUCE 425G | F13: 24 | G13: 1.7 | H13: 1.7 | I13: 72 | J13: =I13*H13 -> 122.4
A14: 11 | C14: 8888626040776 | D14: 701598 | E14: H/FAMILY WHOLE MUSHROOMS 425G | F14: 24 | G14: 1.25 | H14: 1.25 | I14: 192 | J14: =I14*H14 -> 240
A15: 12 | B15: Fried Dace | C15: 8888626168784 | D15: 702759 | E15: H/FAMILY FRIED DACE(PRESER VEG)184G | F15: 24 | G15: 2.49 | H15: 2.49 | I15: 24 | J15: =I15*H15 -> 59.76
A16: 13 | C16: 8888626168791 | D16: 702760 | E16: H/FAMILY FRIED DACE(XO SPICY)184G | F16: 24 | G16: 2.69 | H16: 2.69 | I16: 48 | J16: =I16*H16 -> 129.12
A17: 14 | C17: 8888626168777 | D17: 702758 | E17: H/FAMILY FRIED DACE(BLACK BEANS)184G | F17: 24 | G17: 2.49 | H17: 2.49 | I17: 96 | J17: =I17*H17 -> 239.04
A18: 15 | B18: C.Fruits | C18: 8888626005911 | D18: 701501 | E18: FRUIT KING LYCHEE IN SYRUP 565G | F18: 12 | G18: 1.99 | H18: 1.99 | I18: 84 | J18: =I18*H18 -> 167.16
A19: 16 | C19: 8888626005935 | D19: 701503 | E19: FRUIT KING PINEAPPLE SLICE IN SYRUP567G | F19: 12 | G19: 1.85 | H19: 1.85 | I19: 48 | J19: =I19*H19 -> 88.8
A20: 17 | C20: 8888626005904 | D20: 701500 | E20: FRUIT KING LONGAN IN SYRUP 565G | F20: 12 | G20: 2 | H20: 2 | I20: 84 | J20: =I20*H20 -> 168
A21: 18 | B21: NA | C21: 8888626138589 | D21: 108523 | E21: HAPPY FAMILY CKN RICE CHILLI SAUCE 230G | F21: 24 | G21: 2.4 | H21: 2.4 | I21: 24 | J21: =I21*H21 -> 57.6
A22: 19 | C22: 8888626138503 | D22: 108492 | E22: HAPPY FAMILY NONYA SAMBAL CHILLI 250G | F22: 24 | G22: 2.75 | H22: 2.75 | I22: 48 | J22: =I22*H22 -> 132
A23: 20 | C23: 8888626176185 | D23: 109655 | E23: H/FAMILY PRE LSL SOY SAUCE 500ML | F23: 12 | G23: 1.95 | H23: 1.95 | I23: 48 | J23: =I23*H23 -> 93.6
A24: 21 | C24: 8888626176192 | D24: 109656 | E24: H/FAMILY PRE DARK SOY SAUCE 500ML | F24: 12 | G24: 1.95 | H24: 1.95 | I24: 24 | J24: =I24*H24 -> 46.8
A25: 22 | C25: 8888626166636 | D25: 109265 | E25: HERITAGE FARM TRAD.P/SAUCE 350G | F25: 15 | G25: 2.9 | H25: 2.9 | I25: 45 | J25: =I25*H25 -> 130.5
A26: 23 | C26: 8888626105406 | D26: 108009 | E26: H/FAMILY VINEGAR 640ML | F26: 24 | G26: 1.35 | H26: 1.35 | I26: 48 | J26: =I26*H26 -> 64.8
A27: 24 | C27: 8888626105413 | D27: 108010 | E27: H/FAMILY VINEGAR 5L | F27: 4 | G27: 3.99 | H27: 3.99 | I27: 16 | J27: =I27*H27 -> 63.84
A28: 25 | C28: 8888626065106 | D28: 107026 | E28: H/FAMILY CHILLI SAUCE 500G | F28: 24 | G28: 2.1 | H28: 2.1 | I28: 72 | J28: =I28*H28 -> 151.2
A29: 26 | C29: 8888626065113 | D29: 107027 | E29: H/FAMILY TOMATO SAUCE 485G | F29: 24 | G29: 1.95 | H29: 1.95 | I29: 96 | J29: =I29*H29 -> 187.2
A30: 27 | C30: 8888626005676 | D30: 105481 | E30: H/FAMILY FINE SUGAR 1KG | F30: 24 | G30: 1.69 | H30: 1.69 | I30: 144 | J30: =I30*H30 -> 243.36
A31: 28 | C31: 8888626162430 | D31: 109249 | E31: H/FAMILY BROWN SUGAR 1KG | F31: 12 | G31: 2.2 | H31: 2.2 | I31: 48 | J31: =I31*H31 -> 105.6
A32: 29 | C32: 8888626155203 | D32: 109062 | E32: H/FAMILY HIMALAYAN PINK SALT 400G | F32: 24 | G32: 1.5 | H32: 1.5 | I32: 96 | J32: =I32*H32 -> 144
A33: 30 | C33: 8888626134079 | D33: 108431 | E33: HAPPY FAMILY 100% FRAG SESAME OIL 750ML | F33: 12 | G33: 8.95 | H33: 8.95 | I33: 72 | J33: =I33*H33 -> 644.4
A34: 31 | C34: 8888626174655 | D34: 109654 | E34: H/FAMILY MUSH.VEG OYSTER SAUCE 600G (NEW ARRIVAL) | F34: 9 | G34: 1.99 | H34: 1.99 | I34: 27 | J34: =I34*H34 -> 53.73
A35: 32 | C35: 8888626174525 | D35: 109653 | E35: H/FAMILY PRE OYSTER SAUCE 550G | F35: 12 | G35: 1.95 | H35: 1.95 | I35: 96 | J35: =I35*H35 -> 187.2
A36: Total | J36: =SUM(J4:J35) -> 4922.91

Sheet Snacks 
A1: Ver 2 | B1: Snacks | I1: =Summary!D2 -> 46131
A3: Item No. | B3: Type | C3: Barcode | D3: Item Code | E3: Brand and Product Description | F3: Pack Size | G3: Price | H3: Unit Price | I3: Beginning Units | J3: Total Cost
A4: 1 | B4: Crackers | C4: 8888626086026 | D4: 566362 | E4: H/FAMILY CREAM CRACKERS 8S 176G | F4: 24 | G4: 1.55 | H4: 1.55 | I4: 72 | J4: =I4*H4 -> 111.6
A5: 2 | C5: 8888626174822 | D5: 572863 | E5: H/FAMILY PEANUT BUTTER SANDWICH 290G (NEW ARRIVAL) | F5: 12 | G5: 3 | H5: 3 | I5: 48 | J5: =I5*H5 -> 144
A6: 3 | C6: 8888626117133 | D6: 568210 | E6: H/FAMILY MULTIGRAIN CRACKERS 440G | F6: 20 | G6: 2.99 | H6: 2.99 | I6: 40 | J6: =I6*H6 -> 119.6
A7: 4 | B7: Chips | C7: 8888626153186 | D7: 570597 | E7: HERITAGE FARM Z CUT P/CHIPS ORGN 60G | F7: 12 | G7: 1.15 | H7: 1.15 | I7: 180 | J7: =I7*H7 -> 207
A8: 5 | C8: 8888626153209 | D8: 570599 | E8: HERITAGE FARM Z CUT P/CHIPS H&S 60G | F8: 12 | G8: 1.15 | H8: 1.15 | I8: 72 | J8: =I8*H8 -> 82.8
A9: 6 | B9: Walnut | C9: 8888626167787 | D9: 572059 | E9: H/FAMILY THIN SKINNED WALNUT(ORI)300G | F9: 20 | G9: 3.5 | H9: 3.5 | I9: 40 | J9: =I9*H9 -> 140
A10: 7 | B10: NA | C10: 8888626169408 | D10: 572183 | E10: H/FAMILY SATAY FISH SNACK 40G | F10: 30 | G10: 2.44 | H10: 2.44 | I10: 60 | J10: =I10*H10 -> 146.4
A11: 8 | B11: Baby Biscuits | C11: 686352802877 / 0686352802877 | D11: 863119 | E11: WANT WANT BABY BITES BANANA 50G | F11: 12 | G11: 2.8 | H11: 2.8 | I11: 48 | J11: =I11*H11 -> 134.4
A12: 9 | C12: 015000045203 / 0015000045203 | D12: 861884 | E12: GERBER GRADUATES PUFFS STRAW APPLE 42G | F12: 6 | G12: 5.95 | H12: 5.95 | I12: 60 | J12: =I12*H12 -> 357
A13: 10 | B13: Nuts | C13: 8888626170374 | D13: 572167 | E13: HERITAGE FARM DELIGHT MIX 100G | F13: 10 | G13: 1 | H13: 1 | I13: 40 | J13: =I13*H13 -> 40
A14: 11 | C14: 8888626170367 | D14: 572166 | E14: HERITAGE FARM PEANUT CRACKERS 100G | F14: 10 | G14: 1 | H14: 1 | I14: 20 | J14: =I14*H14 -> 20
A15: 12 | C15: 8888626150383 | D15: 570609 | E15: HERITAGE FARM MACADAMIA AND CASHEW NUTS 150G | F15: 22 | G15: 5.45 | H15: 5.45 | I15: 88 | J15: =I15*H15 -> 479.6
A16: 13 | C16: 8888626150376 | D16: 570608 | E16: HERITAGE FARM WALNUTS AND CASHEW NUTS 150G | F16: 22 | G16: 4.45 | H16: 4.45 | I16: 66 | J16: =I16*H16 -> 293.7
A17: 14 | C17: 8888626150369 | D17: 570607 | E17: HERITAGE FARM ALMOND&CASHEW NUT 150G | F17: 22 | G17: 4.45 | H17: 4.45 | I17: 44 | J17: =I17*H17 -> 195.8
A18: 15 | C18: 8888626150390 | D18: 570610 | E18: HERITAGE FARM M/NUT(CBERRY&RAIS)150G | F18: 22 | G18: 4.45 | H18: 4.45 | I18: 22 | J18: =I18*H18 -> 97.9
A19: 16 | C19: 8888626161792 | D19: 571326 | E19: HERITAGE FARM PREMIUM MIXED NUTS 150G | F19: 22 | G19: 5.45 | H19: 5.45 | I19: 44 | J19: =I19*H19 -> 239.8
A20: 17 | B20: Biscuits | C20: 8888626118000 | D20: 568285 | E20: H/FAMILY MARIE BISCUIT 240G | F20: 12 | G20: 1.75 | H20: 1.75 | I20: 48 | J20: =I20*H20 -> 84
A21: 18 | C21: 8888626158372 | D21: 570939 | E21: H/FAMILY CHOCO CHIPS BISCUITS 160G | F21: 24 | G21: 1.75 | H21: 1.75 | I21: 72 | J21: =I21*H21 -> 126
A22: 19 | C22: 8888626158419 | D22: 570943 | E22: H/FAMILY LEMON DELITE BISCUITS 125G | F22: 24 | G22: 1.2 | H22: 1.2 | I22: 48 | J22: =I22*H22 -> 57.6
A23: 20 | C23: 8888626114668 | D23: 568097 | E23: H/FAMILY H/HOLIDAYS ASST BISCUITS 600G | F23: 6 | G23: 5.99 | H23: 5.99 | I23: 24 | J23: =I23*H23 -> 143.76
A24: 21 | B24: Chestnut | C24: 8888626159805 | D24: 571074 | E24: H/FAMILY ORGANIC ROASTED CHESTNUTS 150G | F24: 40 | G24: 1.35 | H24: 1.35 | I24: 240 | J24: =I24*H24 -> 324
A25: 22 | B25: Popcorn | C25: 8888626181776 | D25: 573030 | E25: HERITAGE FARM ORG POPCORN 180G(N) (NEW ARRIVAL) | F25: 12 | G25: 2.5 | H25: 2.5 | I25: 24 | J25: =I25*H25 -> 60
A26: 23 | C26: 8888626181790 | D26: 573031 | E26: HERITAGE FARM CHEESE POPCORN 180G(N) (NEW ARRIVAL) | F26: 12 | G26: 2.5 | H26: 2.5 | I26: 36 | J26: =I26*H26 -> 90
A27: 24 | C27: 8888626181783 | D27: 573032 | E27: HERITAGE FARM CARAMEL POPCORN 180G(N) (NEW ARRIVAL) | F27: 12 | G27: 2.5 | H27: 2.5 | I27: 48 | J27: =I27*H27 -> 120
A28: 25 | B28: Dried Fruit | C28: 8888626168111 | D28: 571753 | E28: HERITAGE FARM DRIED PRUNES 300G | F28: 8 | G28: 6.95 | H28: 6.95 | I28: 32 | J28: =I28*H28 -> 222.4
A29: 26 | C29: 8888626168128 | D29: 571754 | E29: HERITAGE FARM DRIED MANGO 100G | F29: 24 | G29: 3.2 | H29: 3.2 | I29: 48 | J29: =I29*H29 -> 153.6
A30: 27 | B30: NA | C30: 8888626128801 | D30: 569181 | E30: BAKE FOR YOU HEONG PEAH (ORIGINAL) 360G | F30: 12 | G30: 5.95 | H30: 5.95 | I30: 36 | J30: =I30*H30 -> 214.2
A31: 28 | B31: Seaweed | C31: 8888626159829 | D31: 571096 | E31: H/FARM SE/SEAWEED(PERILLA OIL)4GX8S | F31: 18 | G31: 2.8 | H31: 2.8 | I31: 288 | J31: =I31*H31 -> 806.4
A32: Total | J32: =SUM(J4:J31) -> 5211.56

Sheet Tissue & Others
A1: Ver 2 | B1: Paper Products & Others | I1: =Summary!D2 -> 46131
A3: Item No. | B3: Type | C3: Barcode | D3: Item Code | E3: Brand and Product Description | F3: Pack Size | G3: Price | H3: Unit Price | I3: Beginning Units | J3: Total Cost
A4: 1 | B4: Toilet Roll | C4: 8888626165950 | D4: 1970529 | E4: SOFTESS P/P BR TIS 4PLY(10+2)1.8KG | F4: 6 | G4: 9.8 | H4: 9.8 | I4: 168 | J4: =I4*H4 -> 1646.4
A5: 2 | C5: 8888626066509 | D5: 1970173 | E5: SOFTESS P/P BR TIS 3PLY 3X10X200S(GRN) | F5: 1 | G5: 12.95 | H5: 12.95 | I5: 240 | J5: =I5*H5 -> 3108
A6: 3 | C6: 8888626177663 | D6: 1970620 | E6: SOFTESS P/P BR TIS 3PLY 3X1.8KG(GT) (NEW ARRIVAL) | F6: 1 | G6: 24.95 | H6: 24.95 | I6: 40 | J6: =I6*H6 -> 998
A7: 4 | C7: 8888626176666 | D7: 1970612 | E7: SOFTESS BAMBOO BR TIS 3PLY 10X220S (NEW ARRIVAL) | F7: 10 | G7: 5.5 | H7: 5.5 | I7: 40 | J7: =I7*H7 -> 220
A8: 5 | C8: 8888626064680 | D8: 1970156 | E8: SOFTESS P/P JRT 2PLY 4X180M | F8: 4 | G8: 8.95 | H8: 8.95 | I8: 20 | J8: =I8*H8 -> 179
A9: 6 | B9: Tissue | C9: 8888626165936 | D9: 1970521 | E9: SOFTESS P/P K/TOWEL 8X60S(SFR) | F9: 4 | G9: 5.85 | H9: 5.85 | I9: 400 | J9: =I9*H9 -> 2340
A10: 7 | C10: 8888626175225 | D10: 1970593 | E10: SOFTESS TAD HANGING K/TOWEL 2PLY 180S | F10: 10 | G10: 3.95 | H10: 3.95 | I10: 40 | J10: =I10*H10 -> 158
A11: 8 | C11: 8888626144399 | D11: 1970426 | E11: SOFTESS SOFTPACK TISS 3PLY 10X140S(SFR) | F11: 6 | G11: 9.95 | H11: 9.95 | I11: 300 | J11: =I11*H11 -> 2985
A12: 9 | C12: 8888626176659 | D12: 1970613 | E12: SOFTESS BAMBOO SOFTPACK 4PLY 4X130S (NEW ARRIVAL) | F12: 10 | G12: 6.5 | H12: 6.5 | I12: 30 | J12: =I12*H12 -> 195
A13: 10 | C13: 8888626177694 | D13: 1970622 | E13: SOFTESS P/P BOX TISSUE 4PLY 5X100S | F13: 10 | G13: 5.95 | H13: 5.95 | I13: 70 | J13: =I13*H13 -> 416.5
A14: 11 | C14: 8888626175171 | D14: 1909352 | E14: SOFTESS P/P HANGING F/TISSUES 4PLY 320S | F14: 10 | G14: 2 | H14: 2 | I14: 100 | J14: =I14*H14 -> 200
A15: 12 | C15: 8888626028675 | D15: 1970069 | E15: SOFTESS P/P POCKET TISSUE 3PLY 6X12X8S | F15: 12 | G15: 5.8 | H15: 5.8 | I15: 84 | J15: =I15*H15 -> 487.2
A16: 13 | C16: 8888626140667 | D16: 1970412 | E16: SOFTESS P/P TRAVEL P/TISS 3PX4X50S(KITTY) | F16: 24 | G16: 1.5 | H16: 1.5 | I16: 168 | J16: =I16*H16 -> 252
A17: 14 | C17: 8888626165974 | D17: 1970530 | E17: SOFTESS P/P SOFTPACK TISS 3PLY 6X88S | F17: 10 | G17: 4.95 | H17: 4.95 | I17: 50 | J17: =I17*H17 -> 247.5
A18: 15 | B18: Wet Wipes | C18: 8888626115658 | D18: 1970317 | E18: SOFTESS ADULT BODY WIPES(FRAG FREE)40S | F18: 12 | G18: 2.45 | H18: 2.45 | I18: 48 | J18: =I18*H18 -> 117.6
A19: 16 | C19: 8888626067155 | D19: 1970184 | E19: SOFTESS WET WIPES LAVENDER 4X10S | F19: 24 | G19: 2.85 | H19: 2.85 | I19: 72 | J19: =I19*H19 -> 205.2
A20: 17 | C20: 8888626138558 | D20: 1970372 | E20: SOFTESS AB WET WIPES PINE 50S | F20: 24 | G20: 3 | H20: 3 | I20: 48 | J20: =I20*H20 -> 144
A21: 18 | C21: 8888626167893 | D21: 864174 | E21: SOFTESS 100% PURE WATER BABYWIPES 3X80S | F21: 8 | G21: 6.95 | H21: 6.95 | I21: 40 | J21: =I21*H21 -> 278
A22: 19 | B22: BodyWash | C22: 8888626143828 | D22: 513793 | E22: SOFTESS AB BODY WASH-GOAT MILK 900ML | F22: 12 | G22: 4.95 | H22: 4.95 | I22: 48 | J22: =I22*H22 -> 237.6
A23: 20 | C23: 8888626160191 | D23: 1908863 | E23: POWERPLUS AB B/WASH-LAVENDER EUPHORIA 1L | F23: 12 | G23: 3.8 | H23: 3.8 | I23: 36 | J23: =I23*H23 -> 136.8
A24: 21 | B24: Hand wash | C24: 8888626150321 | D24: 513918 | E24: HOMENIKS GEL HAND SOAP(LAVENDER)500ML | F24: 12 | G24: 2.75 | H24: 2.75 | I24: 72 | J24: =I24*H24 -> 198
A25: 22 | C25: 8888626143699 | D25: 513696 | E25: POWERPLUS AB HANDWASH COOL MINT 3X250ML | F25: 8 | G25: 6.95 | H25: 6.95 | I25: 48 | J25: =I25*H25 -> 333.6
A26: 23 | B26: Mask | C26: 8888626169262 | D26: 9822185 | E26: POWERPLUS 3PLY MEDICAL MASK 50S-BLUE | F26: 20 | G26: 3 | H26: 3 | I26: 80 | J26: =I26*H26 -> 240
A27: 24 | B27: NA | C27: 8888626160221 | D27: 954476 | E27: SOFTESS FACIAL PUFFS 200S(SIDE SEALED) | F27: 8 | G27: 2 | H27: 2 | I27: 48 | J27: =I27*H27 -> 96
A28: 25 | C28: 8888626160238 | D28: 954475 | E28: SOFTESS 3IN1 COTTON BUDS 240SPAPERSTICK | F28: 10 | G28: 2.5 | H28: 2.5 | I28: 30 | J28: =I28*H28 -> 75
A29: 26 | B29: Underpad | C29: 8888626140681 | D29: 1908189 | E29: SOFTESS ABSORBENT UNDERPAD L 10S | F29: 8 | G29: 6.3 | H29: 6.3 | I29: 24 | J29: =I29*H29 -> 151.2
A30: 27 | B30: Baby Diaper | C30: 8888626175195 | D30: 864255 | E30: SOFTESS PREMIUM BABY SLIM PANTS L 46S (NEW ARRIVAL) | F30: 4 | G30: 15 | H30: 15 | I30: 12 | J30: =I30*H30 -> 180
A31: 28 | C31: 8888626175201 | D31: 864256 | E31: SOFTESS PREMIUM BABY SLIM PANTS XL 42S (NEW ARRIVAL) | F31: 4 | G31: 15 | H31: 15 | I31: 28 | J31: =I31*H31 -> 420
A32: 29 | C32: 8888626175218 | D32: 864257 | E32: SOFTESS PREMIUM BABY SLIM PANTS XXL 40S (NEW ARRIVAL) | F32: 4 | G32: 15 | H32: 15 | I32: 32 | J32: =I32*H32 -> 480
A33: 30 | B33: Adult Diaper | C33: 8888626160160 | D33: 1908804 | E33: SOFTESS CLASSIC ADULT PANTS M 18S | F33: 6 | G33: 9.5 | H33: 9.5 | I33: 18 | J33: =I33*H33 -> 171
A34: 31 | C34: 8888626160177 | D34: 1908803 | E34: SOFTESS CLASSIC ADULT PANTS L 16S | F34: 6 | G34: 9.5 | H34: 9.5 | I34: 12 | J34: =I34*H34 -> 114
A35: 32 | C35: 8888626160184 | D35: 1908802 | E35: SOFTESS CLASSIC ADULT PANTS XL 15S | F35: 6 | G35: 9.5 | H35: 9.5 | I35: 18 | J35: =I35*H35 -> 171
A36: 33 | C36: 8888626066493 | D36: 1904953 | E36: SOFTESS ADULT DIAPERS L 8S | F36: 12 | G36: 5.5 | H36: 5.5 | I36: 48 | J36: =I36*H36 -> 264
A37: 34 | C37: 8888626066486 | D37: 1904952 | E37: SOFTESS ADULT DIAPERS M 10S | F37: 12 | G37: 5.5 | H37: 5.5 | I37: 24 | J37: =I37*H37 -> 132
A38: Total | J38: =SUM(J4:J37) -> 17577.6

Sheet Cleaning Agent
A1: Ver 2 | B1: Cleaning Agent | I1: =Summary!D2 -> 46131
A3: Item No. | B3: Type | C3: Barcode | D3: Item Code | E3: Brand and Product Description | F3: Pack Size | G3: Price | H3: Unit Price | I3: Beginning Units | J3: Total Cost
A4: 1 | B4: Bleach | C4: 8888626093864 | D4: 513049 | E4: HOMENIKS BLEACH 3.8L | F4: 6 | G4: 2.55 | H4: 2.55 | I4: 48 | J4: =I4*H4 -> 122.4
A5: 2 | B5: NA | C5: 8888626086606 | D5: 512966 | E5: HOMENIKS AB DETERGENT POWDER 5KG | F5: 3 | G5: 6.99 | H5: 6.99 | I5: 18 | J5: =I5*H5 -> 125.82
A6: 3 | C6: 8888626093604 | D6: 513043 | E6: HOMENIKS AB DETERGENT POWDER 1KG | F6: 15 | G6: 2.2 | H6: 2.2 | I6: 15 | J6: =I6*H6 -> 33
A7: 4 | C7: 8888626149981 | D7: 513899 | E7: HOMENIKS PREMIUM LIQ DETERG(P.WASH)3KG | F7: 4 | G7: 7.95 | H7: 7.95 | I7: 12 | J7: =I7*H7 -> 95.4
A8: 5 | C8: 8888626150000 | D8: 513901 | E8: HOMENIKS PREMIUM LIQ DETERG(S.COL)3KG | F8: 4 | G8: 7.95 | H8: 7.95 | I8: 20 | J8: =I8*H8 -> 159
A9: 6 | C9: 8888626150024 | D9: 513903 | E9: HOMENIKS PREMIUM LIQ DETERG(U.C)REF1.6KG | F9: 8 | G9: 3.3 | H9: 3.3 | I9: 16 | J9: =I9*H9 -> 52.8
A10: 7 | C10: 8888626150031 | D10: 513904 | E10: HOMENIKS PREMIUM LIQ DET(S.COL)REF 1.6KG | F10: 8 | G10: 3.3 | H10: 3.3 | I10: 24 | J10: =I10*H10 -> 79.2
A11: 8 | C11: 8888626168739 | D11: 514338 | E11: HOMENIKS JUMBO L/CAP 46S(B'FLY-BLOS) | F11: 8 | G11: 14.45 | H11: 14.45 | I11: 40 | J11: =I11*H11 -> 578
A12: 9 | C12: 8888626167879 | D12: 514205 | E12: HOMENIKS 6IN1 LAUNDRY CAPSULES(BLOOS)80S | F12: 8 | G12: 8.95 | H12: 8.95 | I12: 120 | J12: =I12*H12 -> 1074
A13: 10 | C13: 8888626167886 | D13: 514206 | E13: HOMENIKS 6IN1 LAUNDRY CAPSULES(LAV) 80S | F13: 8 | G13: 8.95 | H13: 8.95 | I13: 144 | J13: =I13*H13 -> 1288.8
A14: 11 | C14: 8888626117737 | D14: 513281 | E14: HOMENIKS FABRIC SOFTENER LAV(REF)1.8L | F14: 6 | G14: 2.35 | H14: 2.35 | I14: 18 | J14: =I14*H14 -> 42.3
A15: 12 | B15: Dishwashing | C15: 8888626093840 | D15: 513052 | E15: HOMENIKS DISHWASHING LEMON 5L | F15: 4 | G15: 4.05 | H15: 4.05 | I15: 72 | J15: =I15*H15 -> 291.6
A16: 13 | C16: 8888626149950 | D16: 513896 | E16: HOMENIKS DISHWASHING LIQ(CITRUS) 1.1L+RF | F16: 6 | G16: 5.5 | H16: 5.5 | I16: 96 | J16: =I16*H16 -> 528
A17: 14 | C17: 8888626110059 | D17: 513218 | E17: HOMENIKS DISHWASH LIQ REF(MIX) 4X600ML | F17: 6 | G17: 4.65 | H17: 4.65 | I17: 120 | J17: =I17*H17 -> 558
A18: 15 | B18: Disinfecting Wipes | C18: 8888626138572 | D18: 1970374 | E18: HOMENIKS DISINFECTING WIPES FRESH 75S | F18: 6 | G18: 6.5 | H18: 6.5 | I18: 36 | J18: =I18*H18 -> 234
A19: 16 | B19: Glass Cleaner | C19: 8888626092591 | D19: 513023 | E19: HOMENIKS GLASS CLEANER 500ML+REF(ICOOL) | F19: 6 | G19: 3.95 | H19: 3.95 | I19: 18 | J19: =I19*H19 -> 71.1
A20: 17 | B20: Wiper Sheet | C20: 8888626143781 | D20: 953784 | E20: HOMENIKS WET WIPER SHEET 15S(LEMON) | F20: 18 | G20: 2.5 | H20: 2.5 | I20: 36 | J20: =I20*H20 -> 90
A21: 18 | B21: Toilet Cleaner | C21: 8888626142869 | D21: 513674 | E21: HOMENIKS AB TOILET CLEANER-LEMON 3X500ML | F21: 4 | G21: 6.6 | H21: 6.6 | I21: 28 | J21: =I21*H21 -> 184.8
A22: 19 | B22: Multi Purpose Cleaner | C22: 8888626168753 | D22: 514340 | E22: HOMENIKS M/PURPOSE CLEANER(CITRUS) 2L | F22: 6 | G22: 4.35 | H22: 4.35 | I22: 12 | J22: =I22*H22 -> 52.2
A23: 20 | C23: 8888626168746 | D23: 514341 | E23: HOMENIKS M/PURPOSE CLEANER(APPLE) 2L | F23: 6 | G23: 4.35 | H23: 4.35 | I23: 12 | J23: =I23*H23 -> 52.2
A24: 21 | C24: 8888626092522 | D24: 513020 | E24: HOMENIKS M/PURPOSE CLEANER(FLORAL)2L | F24: 6 | G24: 4.35 | H24: 4.35 | I24: 18 | J24: =I24*H24 -> 78.3
A25: 22 | B25: Cleaner - Others | C25: 8888626093857 | D25: 513048 | E25: HOMENIKS PINE DISINFECTANT 5L | F25: 4 | G25: 6.4 | H25: 6.4 | I25: 12 | J25: =I25*H25 -> 76.8
A26: 23 | C26: 8888626087474 | D26: 513001 | E26: HOMENIKS PINE DISINFECTANT 2L | F26: 6 | G26: 4.35 | H26: 4.35 | I26: 18 | J26: =I26*H26 -> 78.3
A27: 24 | C27: 8888626093888 | D27: 513051 | E27: HOMENIKS STAIN REMOVER 1L | F27: 12 | G27: 1.25 | H27: 1.25 | I27: 36 | J27: =I27*H27 -> 45
A28: 25 | B28: Battery | C28: 8888626177496 | D28: 389431 | E28: HOMENIKS ALKALINE BATTERY 1.5V AAA4 | F28: 12 | G28: 1.25 | H28: 1.25 | I28: 120 | J28: =I28*H28 -> 150
A29: 26 | C29: 8888626177502 | D29: 389432 | E29: HOMENIKS ALKALINE BATTERY 1.5V AA4 | F29: 12 | G29: 1.25 | H29: 1.25 | I29: 36 | J29: =I29*H29 -> 45
A30: 27 | B30: Kitchen Wipes | C30: 8888626161693 | D30: 954452 | E30: HOMENIKS AB KITCHEN WIPES 80S | F30: 12 | G30: 4 | H30: 4 | I30: 96 | J30: =I30*H30 -> 384
A31: 28 | B31: NA | C31: 8888626150284 | D31: 953998 | E31: HOMENIKS MT I/KILLER SPRAY-F/ACT 2X625ML | F31: 6 | G31: 9.95 | H31: 9.95 | I31: 60 | J31: =I31*H31 -> 597
A32: 29 | B32: Germicide | C32: 8888626143897 | D32: 513863 | E32: HOMENIKS ANTISEPTIC GERMICIDE 750ML | F32: 6 | G32: 8.8 | H32: 8.8 | I32: 48 | J32: =I32*H32 -> 422.4
A33: 30 | B33: Dehumidifier | C33: 8888626149806 | D33: 513871 | E33: HOMENIKS DEHUMIDIFIER (LAV) 8X720ML | F33: 4 | G33: 8.95 | H33: 8.95 | I33: 52 | J33: =I33*H33 -> 465.4
A34: 31 | B34: NA | C34: 8888626149684 | D34: 953966 | E34: HOMENIKS H/DUTY CELLULOSE SCOURER-3S | F34: 12 | G34: 4.6 | H34: 4.6 | I34: 24 | J34: =I34*H34 -> 110.4
A35: 32 | C35: 8888626149677 | D35: 953965 | E35: HOMENIKS SCOURER PAD-5S | F35: 12 | G35: 2.2 | H35: 2.2 | I35: 24 | J35: =I35*H35 -> 52.8
A36: 33 | C36: 8888626149660 | D36: 953964 | E36: HOMENIKS SPONGE SCOURER REGULAR-4S | F36: 12 | G36: 2.75 | H36: 2.75 | I36: 24 | J36: =I36*H36 -> 66
A37: 34 | C37: 8888626160245 | D37: 954356 | E37: HOMENIKS CLING WRAP 200SQ(61MX30CM) | F37: 24 | G37: 3.95 | H37: 3.95 | I37: 48 | J37: =I37*H37 -> 189.6
A38: 35 | C38: 8888626160252 | D38: 954355 | E38: HOMENIKS BAKING & COOKING PAPER (10MX30CM) | F38: 24 | G38: 2.99 | H38: 2.99 | I38: 48 | J38: =I38*H38 -> 143.52
A39: 36 | C39: 8888626160276 | D39: 954357 | E39: HOMENIKS TRASH BAG 45X60CM(M)3S-(H/T) | F39: 10 | G39: 2.9 | H39: 2.9 | I39: 70 | J39: =I39*H39 -> 203
A40: 37 | C40: 8888626160726 | D40: 954358 | E40: HOMENIKS TRASH BAG 50X70CM(L)3S-(H/T) | F40: 10 | G40: 3 | H40: 3 | I40: 90 | J40: =I40*H40 -> 270
A41: 38 | C41: 8888626160733 | D41: 954359 | E41: HOMENIKS TRASH BAG 60X80CM(XL)1S-(FL) | F41: 24 | G41: 2.3 | H41: 2.3 | I41: 48 | J41: =I41*H41 -> 110.4
...
